<?xml version="1.0"?>
<robot name="my_robot">

  <link name="base_link">
    <visual>
      <geometry>
	<cylinder radius="0.1" length="0.3"/>
      </geometry>
    </visual>
  </link>

  <link name="second_link">
    <visual>
      <geometry>
        <cylinder radius="0.05" length="0.2"/>
      </geometry>
    </visual>
  </link>

  <joint name="joint1" type="revolute">
    <parent link="base_link"/>
    <child link="second_link"/>
    <origin xyz="0 0 0.3" rpy="0 0 0"/>
    <axis xyz="0 1 0"/>
    <limit lower="-1.57" upper="1.57" effort="10" velocity="1"/>
  </joint>

</robot>
